<?xml version="1.0" ?>
<!-- =================================================================================== -->
<!-- |    This document was autogenerated by xacro from robot.urdf.xacro               | -->
<!-- |    EDITING THIS FILE BY HAND IS NOT RECOMMENDED                                 | -->
<!-- =================================================================================== -->
<robot>
  <!-- offset from base_link to base_footprint -->
  <!-- 0 - wheel_radius - distance_to_ground-->
  <!-- Color codes from https://gist.github.com/naoki-mizuno/5e63a13597d5c5fe817c1600b829595e, matches with Gazebo colors with the same name -->
  <material name="lightgrey">
    <color rgba="0.8 0.8 0.8 1.0"/>
  </material>
  <material name="darkgreyrover">
    <color rgba="0.15 0.15 0.15 1.0"/>
  </material>
  <!-- WHEEL_LF TRANSMISSION -->
  <transmission name="trans_lf">
    <type>transmission_interface/SimpleTransmission</type>
    <joint name="joint_lf">
      <hardwareInterface>hardware_interface/VelocityJointInterface</hardwareInterface>
    </joint>
    <actuator name="motor_lf">
      <hardwareInterface>hardware_interface/VelocityJointInterface</hardwareInterface>
      <mechanicalReduction>1</mechanicalReduction>
    </actuator>
  </transmission>
  <!-- WHEEL_LB TRANSMISSION -->
  <transmission name="trans_lb">
    <type>transmission_interface/SimpleTransmission</type>
    <joint name="joint_lb">
      <hardwareInterface>hardware_interface/VelocityJointInterface</hardwareInterface>
    </joint>
    <actuator name="motor_lb">
      <hardwareInterface>hardware_interface/VelocityJointInterface</hardwareInterface>
      <mechanicalReduction>1</mechanicalReduction>
    </actuator>
  </transmission>
  <!-- WHEEL_RF TRANSMISSION -->
  <transmission name="trans_rf">
    <type>transmission_interface/SimpleTransmission</type>
    <joint name="joint_rf">
      <hardwareInterface>hardware_interface/VelocityJointInterface</hardwareInterface>
    </joint>
    <actuator name="motor_rf">
      <hardwareInterface>hardware_interface/VelocityJointInterface</hardwareInterface>
      <mechanicalReduction>1</mechanicalReduction>
    </actuator>
  </transmission>
  <!-- WHEEL_RB TRANSMISSION -->
  <transmission name="trans_rb">
    <type>transmission_interface/SimpleTransmission</type>
    <joint name="joint_rb">
      <hardwareInterface>hardware_interface/VelocityJointInterface</hardwareInterface>
    </joint>
    <actuator name="motor_rb">
      <hardwareInterface>hardware_interface/VelocityJointInterface</hardwareInterface>
      <mechanicalReduction>1</mechanicalReduction>
    </actuator>
  </transmission>
  <!-- **** LINKS **** -->
  <!-- BASE_FOOTPRINT -->
  <link name="base_footprint"/>
  <!-- BASE_LINK -->
  <link name="base_link">
    <visual>
      <origin rpy="0 0 0" xyz="0 0 0"/>
      <geometry>
        <mesh filename="../meshes/rover.stl"/>
      </geometry>
      <material name="lightgrey"/>
    </visual>
    <collision>
      <origin rpy="0 0 0" xyz="0 0 -0.051"/>
      <geometry>
        <box size="0.4 0.307 0.102"/>
      </geometry>
    </collision>
  </link>
  <!-- BASE_LINK_INERTIAL (WORKAROUND FOR KDL WHICH DOES NOT ACCEPT BASE_LINK WITH INERTIA) -->
  <link name="base_link_inertial">
    <inertial>
      <origin rpy="0 0 0" xyz="0 0 0"/>
      <mass value="2.0"/>
      <inertia ixx="0.017442166666666665" ixy="0" ixz="0" iyy="0.02840066666666667" iyz="0" izz="0.02840066666666667"/>
    </inertial>
  </link>
  <!-- WHEEL LEFT FRONT -->
  <link name="wheel_lf">
    <inertial>
      <mass value="0.075"/>
      <inertia ixx="6.250000000000001e-05" ixy="0" ixz="0" iyy="6.250000000000001e-05" iyz="0" izz="9.375e-05"/>
    </inertial>
    <visual>
      <origin rpy="1.5707963 0 0" xyz="0 0 0"/>
      <geometry>
        <mesh filename="../meshes/wheel_lf.stl"/>
      </geometry>
      <material name="darkgreyrover"/>
    </visual>
    <collision>
      <origin rpy="1.5707963 0 0" xyz="0 0.025 0"/>
      <geometry>
        <cylinder length="0.05" radius="0.05"/>
      </geometry>
    </collision>
  </link>
  <!-- WHEEL LEFT BACK -->
  <link name="wheel_lb">
    <inertial>
      <mass value="0.075"/>
      <inertia ixx="6.250000000000001e-05" ixy="0" ixz="0" iyy="6.250000000000001e-05" iyz="0" izz="9.375e-05"/>
    </inertial>
    <visual>
      <origin rpy="1.5707963 0 0" xyz="0 0 0"/>
      <geometry>
        <mesh filename="../meshes/wheel_lb.stl"/>
      </geometry>
      <material name="darkgreyrover"/>
    </visual>
    <collision>
      <origin rpy="1.5707963 0 0" xyz="0 0.025 0"/>
      <geometry>
        <cylinder length="0.05" radius="0.05"/>
      </geometry>
    </collision>
  </link>
  <!-- WHEEL RIGHT FRONT -->
  <link name="wheel_rf">
    <inertial>
      <mass value="0.075"/>
      <inertia ixx="6.250000000000001e-05" ixy="0" ixz="0" iyy="6.250000000000001e-05" iyz="0" izz="9.375e-05"/>
    </inertial>
    <visual>
      <origin rpy="-1.5707963 0 0" xyz="0 0 0"/>
      <geometry>
        <mesh filename="../meshes/wheel_rf.stl"/>
      </geometry>
      <material name="darkgreyrover"/>
    </visual>
    <collision>
      <origin rpy="-1.5707963 0 0" xyz="0 -0.025 0"/>
      <geometry>
        <cylinder length="0.05" radius="0.05"/>
      </geometry>
    </collision>
  </link>
  <!-- WHEEL RIGHT BACK -->
  <link name="wheel_rb">
    <inertial>
      <mass value="0.075"/>
      <inertia ixx="6.250000000000001e-05" ixy="0" ixz="0" iyy="6.250000000000001e-05" iyz="0" izz="9.375e-05"/>
    </inertial>
    <visual>
      <origin rpy="-1.5707963 0 0" xyz="0 0 0"/>
      <geometry>
        <mesh filename="../meshes/wheel_rb.stl"/>
      </geometry>
      <material name="darkgreyrover"/>
    </visual>
    <collision>
      <origin rpy="-1.5707963 0 0" xyz="0 -0.025 0"/>
      <geometry>
        <cylinder length="0.05" radius="0.05"/>
      </geometry>
    </collision>
  </link>
  <!-- **** JOINTS **** -->
  <!-- BASE_LINK TO BASE_FOOTPRINT -->
  <joint name="base_footprint_fixed" type="fixed">
    <parent link="base_footprint"/>
    <child link="base_link"/>
    <origin xyz="0 0 0.125"/>
  </joint>
  <!-- BASE_LINK_INERTIAL TO BASE_LINK -->
  <joint name="base_inertial_fixed" type="fixed">
    <parent link="base_link"/>
    <child link="base_link_inertial"/>
    <origin xyz="0 0 0"/>
  </joint>
  <!-- WHEEL_LF TO BASE_LINK -->
  <joint name="joint_lf" type="continuous">
    <parent link="base_link"/>
    <child link="wheel_lf"/>
    <origin rpy="0 0 0" xyz="0.15 0.1035 -0.073"/>
    <axis xyz="0 1 0"/>
  </joint>
  <!-- WHEEL_LB TO BASE_LINK -->
  <joint name="joint_lb" type="continuous">
    <parent link="base_link"/>
    <child link="wheel_lb"/>
    <origin rpy="0 0 0" xyz="-0.15 0.1035 -0.073"/>
    <axis xyz="0 1 0"/>
  </joint>
  <!-- WHEEL_RF TO BASE_LINK -->
  <joint name="joint_rf" type="continuous">
    <parent link="base_link"/>
    <child link="wheel_rf"/>
    <origin rpy="0 0 0" xyz="0.15 -0.1035 -0.073"/>
    <axis xyz="0 1 0"/>
  </joint>
  <!-- WHEEL_RB TO BASE_LINK -->
  <joint name="joint_rb" type="continuous">
    <parent link="base_link"/>
    <child link="wheel_rb"/>
    <origin rpy="0 0 0" xyz="-0.15 -0.1035 -0.073"/>
    <axis xyz="0 1 0"/>
  </joint>
</robot>
